Workbook

Sheet Sheet1
A1: check | B1: (All)
A4: transfermarkt_id | B4: explanation
A5: 65 | B5: first scrap players fbref
A6: 65 Total
A7: 68 | B7: first scrap players fbref
A8: 68 Total
A9: 122 | B9: first scrap players fbref
A10: 122 Total
A11: 132 | B11: first scrap players fbref
A12: 132 Total
A13: 201 | B13: first scrap players fbref
A14: 201 Total
A15: 215 | B15: first scrap players fbref
A16: 215 Total
A17: 488 | B17: first scrap players fbref
A18: 488 Total
A19: 597 | B19: first scrap players fbref
A20: 597 Total
A21: 670 | B21: first scrap players fbref
A22: 670 Total
A23: 690 | B23: first scrap players fbref
A24: 690 Total
A25: 1094 | B25: first scrap players fbref
A26: 1094 Total
A27: 1320 | B27: first scrap players fbref
A28: 1320 Total
A29: 1321 | B29: first scrap players fbref
A30: 1321 Total
A31: 1327 | B31: first scrap players fbref
A32: 1327 Total
A33: 1368 | B33: first scrap players fbref
A34: 1368 Total
A35: 1397 | B35: first scrap players fbref
A36: 1397 Total
A37: 1423 | B37: first scrap players fbref
A38: 1423 Total
A39: 1443 | B39: first scrap players fbref
A40: 1443 Total
A41: 1573 | B41: first scrap players fbref
A42: 1573 Total
...

Sheet premier_fbref2
A1: transfermarkt_id | B1: player_name | C1: player_url | D1: name_home_country | E1: dob_age | F1: place_birth | G1: height | H1: citizenship | I1: position | J1: foot | K1: debut_season | L1: debut_age | M1: first_club | N1: debut_year | O1: check | P1: transfermarkt_url | Q1: explanation
A2: 65 | B2: Dimitar Berbatov | C2: https://fbref.com/en/players/f5781978/Dimitar-Berbatov | D2: Not found | E2: 29616 | F2: Not found | G2: 189 | H2: Bulgaria | I2: FW | J2: Right | K2: 2000-2001 | L2: 19 years | M2: Leverkusen | N2: 2000 | O2: =VLOOKUP(A2,Sheet3!A:Q,17,0) -> #N/A | P2: https://www.transfermarkt.com/dimitar-berbatov/profil/spieler/65 | Q2: first scrap players fbref
A3: 68 | B3: Landon Donovan | C3: https://fbref.com/en/players/594d4046/Landon-Donovan | D3: Not found | E3: 30014 | F3: Not found | G3: 173 | H3: United States | I3: FW-MF (AM-WM) | J3: Both | K3: 2001 | L3: 18 years | M3: SJ Earthquakes | N3: Not found | O3: =VLOOKUP(A3,Sheet3!A:Q,17,0) -> #N/A | P3: https://www.transfermarkt.com/landon-donovan/profil/spieler/68 | Q3: first scrap players fbref
A4: 122 | B4: Jens Lehmann | C4: https://fbref.com/en/players/d1ca1129/Jens-Lehmann | D4: Not found | E4: 25517 | F4: Not found | G4: 190 | H4: Germany | I4: GK | J4: Not found | K4: 1991-1992 | L4: 21 years | M4: Schalke 04 | N4: 1991 | O4: =VLOOKUP(A4,Sheet3!A:Q,17,0) -> #N/A | P4: https://www.transfermarkt.com/jens-lehmann/profil/spieler/122 | Q4: first scrap players fbref
A5: 132 | B5: TomÃ¡Å¡ RosickÃ½ | C5: https://fbref.com/en/players/dbb688e3/Tomas-Rosicky | D5: Not found | E5: 29498 | F5: Not found | G5: 180 | H5: Czech Republic | I5: MF (AM-WM) | J5: Both | K5: 2000-2001 | L5: 19 years | M5: Dortmund | N5: 2000 | O5: =VLOOKUP(A5,Sheet3!A:Q,17,0) -> #N/A | P5: https://www.transfermarkt.com/tom-rosick/profil/spieler/132 | Q5: first scrap players fbref
A6: 201 | B6: Owen Hargreaves | C6: https://fbref.com/en/players/1b2b5b86/Owen-Hargreaves | D6: Not found | E6: 29606 | F6: Not found | G6: 180 | H6: England eng Â Other:Â Canada | I6: MF | J6: Not found | K6: 2000-2001 | L6: 19 years | M6: Bayern Munich | N6: 2000 | O6: =VLOOKUP(A6,Sheet3!A:Q,17,0) -> #N/A | P6: https://www.transfermarkt.com/owen-hargreaves/profil/spieler/201 | Q6: first scrap players fbref
A7: 215 | B7: Roque Santa Cruz | C7: https://fbref.com/en/players/7f2107eb/Roque-Santa-Cruz | D7: Not found | E7: August 16, 1981 (Age:Â 44-101d) | F7: Luque, Paraguay | G7: 191 | H7: Paraguay | I7: FW | J7: Right | K7: 1999-2000 | L7: 17 years | M7: Bayern Munich | N7: 1999 | O7: =VLOOKUP(A7,Sheet3!A:Q,17,0) -> #N/A | P7: https://www.transfermarkt.com/roque-santa-cruz/profil/spieler/215 | Q7: first scrap players fbref
A8: 488 | B8: Gerhard Tremmel | C8: https://fbref.com/en/players/4370cecc/Gerhard-Tremmel | D8: Not found | E8: 28810 | F8: Not found | G8: 190 | H8: Not found | I8: GK | J8: Right | K8: 1999-2000 | L8: 20 years | M8: Unterhaching | N8: 1999 | O8: =VLOOKUP(A8,Sheet3!A:Q,17,0) -> #N/A | P8: https://www.transfermarkt.com/gerhard-tremmel/profil/spieler/488 | Q8: first scrap players fbref
A9: 597 | B9: Alexander Hleb | C9: https://fbref.com/en/players/35cf43aa/Alexander-Hleb | D9: Not found | E9: 29707 | F9: Not found | G9: 185 | H9: Belarus | I9: MF (AM-WM) | J9: Both | K9: 2000-2001 | L9: 19 years | M9: Stuttgart | N9: 2000 | O9: =VLOOKUP(A9,Sheet3!A:Q,17,0) -> #N/A | P9: https://www.transfermarkt.com/alexander-hleb/profil/spieler/597 | Q9: first scrap players fbref
A10: 670 | B10: Martin Petrov | C10: https://fbref.com/en/players/011360ce/Martin-Petrov | D10: Not found | E10: 28870 | F10: Not found | G10: 179 | H10: Bulgaria | I10: FW-MF (WM, left) | J10: Not found | K10: 2001-2002 | L10: 22 years | M10: Wolfsburg | N10: 2001 | O10: =VLOOKUP(A10,Sheet3!A:Q,17,0) -> #N/A | P10: https://www.transfermarkt.com/martin-petrov/profil/spieler/670 | Q10: first scrap players fbref
A11: 690 | B11: Ivan KlasniÄ‡ | C11: https://fbref.com/en/players/214ed478/Ivan-Klasnic | D11: Not found | E11: 29249 | F11: Not found | G11: 186 | H11: Croatia hr Â Other:Â Germany | I11: FW | J11: Not found | K11: 2001-2002 | L11: 21 years | M11: Werder Bremen | N11: 2001 | O11: =VLOOKUP(A11,Sheet3!A:Q,17,0) -> #N/A | P11: https://www.transfermarkt.com/ivan-klasni/profil/spieler/690 | Q11: first scrap players fbref
A12: 1094 | B12: Emanuel Pogatetz | C12: https://fbref.com/en/players/6b08d120/Emanuel-Pogatetz | D12: Not found | E12: 30332 | F12: Not found | G12: 190 | H12: Austria | I12: DF (CB-FB, left) | J12: Left | K12: 2003-2004 | L12: 20 years | M12: Grazer AK | N12: 2003 | O12: =VLOOKUP(A12,Sheet3!A:Q,17,0) -> #N/A | P12: https://www.transfermarkt.com/emanuel-pogatetz/profil/spieler/1094 | Q12: first scrap players fbref
A13: 1320 | B13: Tomasz Kuszczak | C13: https://fbref.com/en/players/a924380b/Tomasz-Kuszczak | D13: Not found | E13: 30030 | F13: Not found | G13: 191 | H13: Poland | I13: GK | J13: Right | K13: 2004-2005 | L13: 22 years | M13: West Brom | N13: 2004 | O13: =VLOOKUP(A13,Sheet3!A:Q,17,0) -> #N/A | P13: https://www.transfermarkt.com/tomasz-kuszczak/profil/spieler/1320 | Q13: first scrap players fbref
A14: 1321 | B14: Jermaine Jones | C14: https://fbref.com/en/players/0c577541/Jermaine-Jones | D14: Not found | E14: 29893 | F14: Not found | G14: 184 | H14: United States us Â Other:Â Germany | I14: MF (AM-DM) | J14: Both | K14: 2000-2001 | L14: 18 years | M14: Eint Frankfurt | N14: 2000 | O14: =VLOOKUP(A14,Sheet3!A:Q,17,0) -> #N/A | P14: https://www.transfermarkt.com/jermaine-jones/profil/spieler/1321 | Q14: first scrap players fbref
A15: 1327 | B15: Alou Diarra | C15: https://fbref.com/en/players/9b74ce00/Alou-Diarra | D15: Not found | E15: 29782 | F15: Not found | G15: 190 | H15: France | I15: MF (DM) | J15: Right | K15: 2002-2003 | L15: 21 years | M15: Le Havre | N15: 2002 | O15: =VLOOKUP(A15,Sheet3!A:Q,17,0) -> #N/A | P15: https://www.transfermarkt.com/alou-diarra/profil/spieler/1327 | Q15: first scrap players fbref
A16: 1368 | B16: Guy Demel | C16: https://fbref.com/en/players/605bba68/Guy-Demel | D16: Not found | E16: 29750 | F16: Not found | G16: 189 | H16: CÃ´te d'Ivoire ci Â Other:Â France | I16: DF-MF (FB, right) | J16: Right | K16: 2002-2003 | L16: 21 years | M16: Dortmund | N16: 2002 | O16: =VLOOKUP(A16,Sheet3!A:Q,17,0) -> #N/A | P16: https://www.transfermarkt.com/guy-demel/profil/spieler/1368 | Q16: first scrap players fbref
A17: 1397 | B17: Michael Owen | C17: https://fbref.com/en/players/88b3f52c/Michael-Owen | D17: Not found | E17: 29203 | F17: Not found | G17: 172 | H17: England eng | I17: FW | J17: Not found | K17: 1996-1997 | L17: 16 years | M17: Liverpool | N17: 1996 | O17: =VLOOKUP(A17,Sheet3!A:Q,17,0) -> #N/A | P17: https://www.transfermarkt.com/michael-owen/profil/spieler/1397 | Q17: first scrap players fbref
A18: 1423 | B18: Lars Jacobsen | C18: https://fbref.com/en/players/bef72e41/Lars-Jacobsen | D18: Not found | E18: 29118 | F18: Not found | G18: 181 | H18: Denmark | I18: DF (CB-FB, right) | J18: Both | K18: 2002-2003 | L18: 22 years | M18: Hamburger SV | N18: 2002 | O18: =VLOOKUP(A18,Sheet3!A:Q,17,0) -> #N/A | P18: https://www.transfermarkt.com/lars-jacobsen/profil/spieler/1423 | Q18: first scrap players fbref
A19: 1443 | B19: Christian Poulsen | C19: https://fbref.com/en/players/4b83b362/Christian-Poulsen | D19: Not found | E19: 29279 | F19: Not found | G19: 182 | H19: Denmark | I19: MF (DM) | J19: Not found | K19: 2002-2003 | L19: 22 years | M19: Schalke 04 | N19: 2002 | O19: =VLOOKUP(A19,Sheet3!A:Q,17,0) -> #N/A | P19: https://www.transfermarkt.com/christian-poulsen/profil/spieler/1443 | Q19: first scrap players fbref
... A22: 2514 | B22: Bastian Schweinsteiger | C22: https://fbref.com/en/players/ccc22fea/Bastian-Schweinsteiger | D22: Not found | E22: 30895 | F22: Not found | G22: 183 | H22: Germany | I22: DF-MF (CB) | J22: Right | K22: 2002-2003 | L22: 17 years | M22: Bayern Munich | N22: 2002 | O22: =VLOOKUP(A22,Sheet3!A:Q,17,0) -> #N/A | P22: https://www.transfermarkt.com/bastian-schweinsteiger/profil/spieler/2514 | Q22: first scrap players fbref
A23: 2857 | B23: Eldin JakupoviÄ‡ | C23: https://fbref.com/en/players/1148323a/Eldin-Jakupovic | D23: Not found | E23: October 2, 1984 (Age:Â 41-054d) | F23: Kozarac, Bosnia and Herzegovina | G23: 191 | H23: Switzerland ch Â Other:Â Bosnia and Herzegovina | I23: GK | J23: Right | K23: 2004-2005 | L23: 19 years | M23: Grasshopper | N23: 2004 | O23: =VLOOKUP(A23,Sheet3!A:Q,17,0) -> #N/A | P23: https://www.transfermarkt.com/eldin-jakupovi/profil/spieler/2857 | Q23: first scrap players fbref
A24: 2874 | B24: Mladen PetriÄ‡ | C24: https://fbref.com/en/players/2cc63c53/Mladen-Petric | D24: Not found | E24: 29587 | F24: Not found | G24: 185 | H24: Croatia hr Â Other:Â Bosnia and Herzegovina | I24: FW | J24: Left | K24: 2003-2004 | L24: 22 years | M24: Grasshopper | N24: 2003 | O24: =VLOOKUP(A24,Sheet3!A:Q,17,0) -> #N/A | P24: https://www.transfermarkt.com/mladen-petri/profil/spieler/2874 | Q24: first scrap players fbref
A25: 2953 | B25: Paul Scharner | C25: https://fbref.com/en/players/d8bcce3d/Paul-Scharner | D25: Not found | E25: 29291 | F25: Not found | G25: 191 | H25: Austria | I25: DF-MF (CB-DM) | J25: Not found | K25: 2003-2004 | L25: 23 years | M25: Austria Wien | N25: 2003 | O25: =VLOOKUP(A25,Sheet3!A:Q,17,0) -> #N/A | P25: https://www.transfermarkt.com/paul-scharner/profil/spieler/2953 | Q25: first scrap players fbref
A26: 2963 | B26: MartÃ­n Demichelis | C26: https://fbref.com/en/players/e9c7102a/Martin-Demichelis | D26: Not found | E26: 29575 | F26: Not found | G26: 184 | H26: Argentina | I26: DF-MF (CB-DM) | J26: Right | K26: 2003-2004 | L26: 22 years | M26: Bayern Munich | N26: 2003 | O26: =VLOOKUP(A26,Sheet3!A:Q,17,0) -> #N/A | P26: https://www.transfermarkt.com/martn-demichelis/profil/spieler/2963 | Q26: first scrap players fbref
A27: 2998 | B27: Robert Huth | C27: https://fbref.com/en/players/0bd1ea64/Robert-Huth | D27: Not found | E27: 30912 | F27: Not found | G27: 191 | H27: Germany | I27: DF (CB) | J27: Right | K27: 2001-2002 | L27: 16 years | M27: Chelsea | N27: 2001 | O27: =VLOOKUP(A27,Sheet3!A:Q,17,0) -> #N/A | P27: https://www.transfermarkt.com/robert-huth/profil/spieler/2998 | Q27: first scrap players fbref
A28: 3091 | B28: Benni McCarthy | C28: https://fbref.com/en/players/a6f401c6/Benni-McCarthy | D28: Not found | E28: 28441 | F28: Not found | G28: 183 | H28: South Africa | I28: FW | J28: Not found | K28: 1999-2000 | L28: 21 years | M28: Celta Vigo | N28: 1999 | O28: =VLOOKUP(A28,Sheet3!A:Q,17,0) -> #N/A | P28: https://www.transfermarkt.com/benni-mccarthy/profil/spieler/3091 | Q28: first scrap players fbref
A29: 3092 | B29: Jason Euell | C29: https://fbref.com/en/players/d97fe8bd/Jason-Euell | D29: Not found | E29: 28162 | F29: Not found | G29: 180 | H29: Jamaica jm Â Other:Â England | I29: FW-MF (CM) | J29: Not found | K29: 1995-1996 | L29: 18 years | M29: Wimbledon | N29: 1995 | O29: =VLOOKUP(A29,Sheet3!A:Q,17,0) -> #N/A | P29: https://www.transfermarkt.com/jason-euell/profil/spieler/3092 | Q29: first scrap players fbref
A30: 3109 | B30: Steven Gerrard | C30: https://fbref.com/en/players/caeb5442/Steven-Gerrard | D30: Not found | E30: 29371 | F30: Not found | G30: 183 | H30: England eng | I30: MF | J30: Right | K30: 1998-1999 | L30: 18 years | M30: Liverpool | N30: 1998 | O30: =VLOOKUP(A30,Sheet3!A:Q,17,0) -> #N/A | P30: https://www.transfermarkt.com/steven-gerrard/profil/spieler/3109 | Q30: first scrap players fbref
A31: 3112 | B31: James Beattie | C31: https://fbref.com/en/players/7c881089/James-Beattie | D31: Not found | E31: 28548 | F31: Not found | G31: 185 | H31: England eng | I31: FW | J31: Not found | K31: 1996-1997 | L31: 18 years | M31: Blackburn | N31: 1996 | O31: =VLOOKUP(A31,Sheet3!A:Q,17,0) -> #N/A | P31: https://www.transfermarkt.com/james-beattie/profil/spieler/3112 | Q31: first scrap players fbref
A32: 3118 | B32: Kieron Dyer | C32: https://fbref.com/en/players/90b5a2f2/Kieron-Dyer | D32: Not found | E32: 28853 | F32: Not found | G32: 173 | H32: England eng | I32: MF (AM-WM) | J32: Not found | K32: 1999-2000 | L32: 20 years | M32: Newcastle Utd | N32: 1999 | O32: =VLOOKUP(A32,Sheet3!A:Q,17,0) -> #N/A | P32: https://www.transfermarkt.com/kieron-dyer/profil/spieler/3118 | Q32: first scrap players fbref
A33: 3130 | B33: Titus Bramble | C33: https://fbref.com/en/players/83ac7c3c/Titus-Bramble | D33: Not found | E33: 29798 | F33: Not found | G33: 185 | H33: England eng | I33: DF (CB) | J33: Not found | K33: 2000-2001 | L33: 19 years | M33: Ipswich Town | N33: 2000 | O33: =VLOOKUP(A33,Sheet3!A:Q,17,0) -> #N/A | P33: https://www.transfermarkt.com/titus-bramble/profil/spieler/3130 | Q33: first scrap players fbref
A34: 3131 | B34: Kevin Phillips | C34: https://fbref.com/en/players/23d97ca1/Kevin-Phillips | D34: Not found | E34: 26870 | F34: Not found | G34: 170 | H34: England eng | I34: FW | J34: Not found | K34: 1999-2000 | L34: 26 years | M34: Sunderland | N34: 1999 | O34: =VLOOKUP(A34,Sheet3!A:Q,17,0) -> #N/A | P34: https://www.transfermarkt.com/kevin-phillips/profil/spieler/3131 | Q34: first scrap players fbref
A35: 3142 | B35: Emile Heskey | C35: https://fbref.com/en/players/30184789/Emile-Heskey | D35: Not found | E35: 28501 | F35: Not found | G35: 192 | H35: England eng | I35: FW | J35: Right | K35: 1994-1995 | L35: 16 years | M35: Leicester City | N35: 1994 | O35: =VLOOKUP(A35,Sheet3!A:Q,17,0) -> #N/A | P35: https://www.transfermarkt.com/emile-heskey/profil/spieler/3142 | Q35: first scrap players fbref
... A72: 3332 | B72: Wayne Rooney | C72: https://fbref.com/en/players/f07be45a/Wayne-Rooney | D72: Not found | E72: 31344 | F72: Not found | G72: 176 | H72: England eng | I72: FW-MF (AM) | J72: Right | K72: 2002-2003 | L72: 16 years | M72: Everton | N72: 2002 | O72: =VLOOKUP(A72,Sheet3!A:Q,17,0) -> #N/A | P72: https://www.transfermarkt.com/wayne-rooney/profil/spieler/3332 | Q72: first scrap players fbref
A73: 3333 | B73: James Milner | C73: https://fbref.com/en/players/2f90f6b8/James-Milner | D73: Not found | E73: January 4, 1986 (Age:Â 39-325d) | F73: Leeds, England, United Kingdom | G73: 176 | H73: England eng | I73: DF-MF (CM-FB-WM) | J73: Right | K73: 2002-2003 | L73: 16 years | M73: Leeds United | N73: 2002 | O73: =VLOOKUP(A73,Sheet3!A:Q,17,0) -> #N/A | P73: https://www.transfermarkt.com/james-milner/profil/spieler/3333 | Q73: first scrap players fbref
A74: 3356 | B74: Sylvain Distin | C74: https://fbref.com/en/players/002d06bb/Sylvain-Distin | D74: Not found | E74: 28475 | F74: Not found | G74: 192 | H74: Not found | I74: DF (CB) | J74: Left | K74: 2000-2001 | L74: 22 years | M74: Paris S-G | N74: 2000 | O74: =VLOOKUP(A74,Sheet3!A:Q,17,0) -> #N/A | P74: https://www.transfermarkt.com/sylvain-distin/profil/spieler/3356 | Q74: first scrap players fbref
A75: 3357 | B75: Mark Schwarzer | C75: https://fbref.com/en/players/da409c6f/Mark-Schwarzer | D75: Not found | E75: 26578 | F75: Not found | G75: 194 | H75: Australia | I75: GK | J75: Right | K75: 1994-1995 | L75: 21 years | M75: Dresden | N75: 1994 | O75: =VLOOKUP(A75,Sheet3!A:Q,17,0) -> #N/A | P75: https://www.transfermarkt.com/mark-schwarzer/profil/spieler/3357 | Q75: first scrap players fbref
A76: 3360 | B76: Ledley King | C76: https://fbref.com/en/players/83ca192d/Ledley-King | D76: Not found | E76: 29506 | F76: Not found | G76: 188 | H76: England eng | I76: DF-MF (CB-DM) | J76: Not found | K76: 1998-1999 | L76: 17 years | M76: Tottenham | N76: 1998 | O76: =VLOOKUP(A76,Sheet3!A:Q,17,0) -> #N/A | P76: https://www.transfermarkt.com/ledley-king/profil/spieler/3360 | Q76: first scrap players fbref
A77: 3397 | B77: Paul Scholes | C77: https://fbref.com/en/players/24a3a72c/Paul-Scholes | D77: Not found | E77: 27349 | F77: Not found | G77: 171 | H77: England eng | I77: MF (CM) | J77: Not found | K77: 1994-1995 | L77: 19 years | M77: Manchester Utd | N77: 1994 | O77: =VLOOKUP(A77,Sheet3!A:Q,17,0) -> #N/A | P77: https://www.transfermarkt.com/paul-scholes/profil/spieler/3397 | Q77: first scrap players fbref
A78: 3403 | B78: Gary Neville | C78: https://fbref.com/en/players/1b013e33/Gary-Neville | D78: Not found | E78: 27443 | F78: Not found | G78: 180 | H78: England eng | I78: DF (FB, right) | J78: Not found | K78: 1993-1994 | L78: 18 years | M78: Manchester Utd | N78: 1993 | O78: =VLOOKUP(A78,Sheet3!A:Q,17,0) -> #N/A | P78: https://www.transfermarkt.com/gary-neville/profil/spieler/3403 | Q78: first scrap players fbref
...

Sheet Sheet3
A1: transfermarkt_id | B1: player_name | C1: player_url | D1: status | E1: name_home_country | F1: dob_age | G1: place_birth | H1: height | I1: citizenship | J1: position | K1: foot | L1: debut_season | M1: debut_age | N1: first_club | O1: debut_year | P1: transfermarkt_url | Q1: check | R1: explanation
A2: 112515 | B2: Marcos Alonso | C2: https://fbref.com/en/players/f4290206/Marcos-Alonso | D2: Success | E2: Not found | F2: December 28, 1990 (Age:Â 34-343d) | G2: Madrid, Spain | H2: 188cm | I2: Spain | J2: DF-MF (CB-DM-FB-WM, left) | K2: Left | L2: 2009-2010 | M2: 18 years | N2: Real Madrid | O2: 2009 | P2: https://www.transfermarkt.com/marcos-alonso/profil/spieler/112515 | Q2: debe tenenr un solo urkl | R2: players corrected fbref
A3: 20714 | B3: Tal Ben Haim | C3: https://fbref.com/en/players/2277a390/Tal-Ben-Haim | D3: Success | E3: Not found | F3: 30041 | G3: Not found | H3: 183cm | I3: Israel | J3: DF (CB-FB, right) | K3: Right | L3: 2004-2005 | M3: 22 years | N3: Bolton | O3: 2004 | P3: https://www.transfermarkt.com/tal-ben-haim/profil/spieler/20714 | Q3: debe tenenr un solo urkl | R3: players corrected fbref
A4: 42411 | B4: Fraizer Campbell | C4: https://fbref.com/en/players/81d63375/Fraizer-Campbell | D4: Success | E4: Not found | F4: 32033 | G4: Not found | H4: 180cm | I4: England eng | J4: FW | K4: Right | L4: 2007-2008 | M4: 19 years | N4: Hull City | O4: 2007 | P4: https://www.transfermarkt.com/fraizer-campbell/profil/spieler/42411 | Q4: debe tenenr un solo urkl | R4: players corrected fbref
A5: 42411 | B5: Fraizer Campbell | C5: https://fbref.com/en/players/81d63375/Fraizer-Campbell | D5: Success | E5: Not found | F5: 32033 | G5: Not found | H5: 180cm | I5: England eng | J5: FW | K5: Right | L5: 2007-2008 | M5: 19 years | N5: Hull City | O5: 2007 | P5: https://www.transfermarkt.com/lee-camp/profil/spieler/42411 | Q5: debe tenenr un solo urkl | R5: players corrected fbref
A6: 21354 | B6: Marek ÄŒech | C6: https://fbref.com/en/players/4261b6d5/Marek-Cech | D6: Success | E6: Not found | F6: 30342 | G6: Not found | H6: 183cm | I6: Slovakia | J6: DF (FB, left) | K6: Not found | L6: 2005-2006 | M6: 22 years | N6: Porto | O6: 2005 | P6: https://www.transfermarkt.com/marek-ech/profil/spieler/21354 | Q6: debe tenenr un solo urkl | R6: players corrected fbref
A7: 12691 | B7: James Collins | C7: https://fbref.com/en/players/c61f1719/James-Collins | D7: Success | E7: Not found | F7: 30551 | G7: Not found | H7: 188cm | I7: Wales wls | J7: DF (CB) | K7: Right | L7: 2002-2003 | M7: 18 years | N7: Cardiff City | O7: 2002 | P7: https://www.transfermarkt.com/james-collins/profil/spieler/12691 | Q7: debe tenenr un solo urkl | R7: players corrected fbref
A8: 42352 | B8: DenÃ­lson | C8: https://fbref.com/en/players/2f07dee0/Denilson | D8: Success | E8: Not found | F8: 32189 | G8: Not found | H8: 179cm | I8: Brazil | J8: MF | K8: Right | L8: 2006-2007 | M8: 18 years | N8: Arsenal | O8: 2006 | P8: https://www.transfermarkt.com/denilson/profil/spieler/42352 | Q8: debe tenenr un solo urkl | R8: players corrected fbref
A9: 4068 | B9: Rob Edwards | C9: https://fbref.com/en/players/270efb21/Rob-Edwards | D9: Success | E9: Not found | F9: 30310 | G9: Not found | H9: 185cm | I9: Wales wls Â Other:Â England | J9: DF | K9: Not found | L9: 2002-2003 | M9: 19 years | N9: Aston Villa | O9: 2002 | P9: https://www.transfermarkt.com/rob-edwards/profil/spieler/4068 | Q9: debe tenenr un solo urkl | R9: players corrected fbref
A10: 9832 | B10: Paulo Ferreira | C10: https://fbref.com/en/players/4ca16d65/Paulo-Ferreira | D10: Success | E10: Not found | F10: 28873 | G10: Not found | H10: 182cm | I10: Portugal | J10: DF (FB) | K10: Not found | L10: 2001-2002 | M10: 22 years | N10: VitÃ³ria SetÃºbal | O10: 2001 | P10: https://www.transfermarkt.com/paulo-ferreira/profil/spieler/9832 | Q10: debe tenenr un solo urkl | R10: players corrected fbref
A11: 50935 | B11: Javier HernÃ¡ndez | C11: https://fbref.com/en/players/189cee7b/Javier-Hernandez | D11: Success | E11: Not found | F11: June 1, 1988 (Age:Â 37-188d) | G11: Guadalajara, Estado de Jalisco, Mexico | H11: 175cm | I11: Mexico | J11: FW | K11: Right | L11: 2006-2007 | M11: 18 years | N11: Guadalajara | O11: 2006 | P11: https://www.transfermarkt.com/javier-hernndez/profil/spieler/50935 | Q11: debe tenenr un solo urkl | R11: players corrected fbref
A12: 34156 | B12: JÃ´ | C12: https://fbref.com/en/players/e47d11f8/Jo | D12: Success | E12: Not found | F12: March 20, 1987 (Age:Â 38-261d) | G12: SÃ£o Paulo, Brazil | H12: 189cm | I12: Brazil | J12: FW | K12: Left | L12: 2006 | M12: 18 years | N12: CSKA Moscow | O12: Not found | P12: https://www.transfermarkt.com/j/profil/spieler/34156 | Q12: debe tenenr un solo urkl | R12: players corrected fbref
A13: 38773 | B13: Eddie Johnson | C13: https://fbref.com/en/players/3552c7f5/Eddie-Johnson | D13: Success | E13: Not found | F13: 30772 | G13: Not found | H13: 183cm | I13: United States | J13: FW | K13: Right | L13: 2001 | M13: 16 years | N13: Dallas Burn | O13: Not found | P13: https://www.transfermarkt.com/eddie-johnson/profil/spieler/38773 | Q13: debe tenenr un solo urkl | R13: players corrected fbref
A14: 44966 | B14: AdriÃ¡n LÃ³pez | C14: https://fbref.com/en/players/70392341/Adrian-Lopez | D14: Success | E14: Not found | F14: 31833 | G14: Not found | H14: 184cm | I14: Not found | J14: DF (CB) | K14: Right | L14: 2007-2008 | M14: 20 years | N14: La CoruÃ±a | O14: 2007 | P14: https://www.transfermarkt.com/adrian-lopez/profil/spieler/44966 | Q14: debe tenenr un solo urkl | R14: players corrected fbref
A15: 33706 | B15: Nani | C15: https://fbref.com/en/players/15e9c7e6/Nani | D15: Success | E15: Not found | F15: 31733 | G15: Not found | H15: 175cm | I15: Portugal | J15: FW-MF (AM-WM) | K15: Right | L15: 2005-2006 | M15: 18 years | N15: Sporting CP | O15: 2005 | P15: https://www.transfermarkt.com/nani/profil/spieler/33706 | Q15: debe tenenr un solo urkl | R15: players corrected fbref
A16: 54170 | B16: Ramires | C16: https://fbref.com/en/players/4cce2c67/Ramires | D16: Success | E16: Not found | F16: 31860 | G16: Not found | H16: 180cm | I16: Brazil | J16: MF (CM-DM-WM) | K16: Right | L16: 2009-2010 | M16: 22 years | N16: Benfica | O16: 2009 | P16: https://www.transfermarkt.com/ramires/profil/spieler/54170 | Q16: debe tenenr un solo urkl | R16: players corrected fbref
A17: 50057 | B17: Aaron Ramsey | C17: https://fbref.com/en/players/ef619b0b/Aaron-Ramsey | D17: Success | E17: Not found | F17: December 26, 1990 (Age:Â 34-345d) | G17: Caerphilly, Wales, United Kingdom | H17: 182cm | I17: Wales wls | J17: MF (AM-CM-DM) | K17: Right | L17: 2007-2008 | M17: 16 years | N17: Cardiff City | O17: 2007 | P17: https://www.transfermarkt.com/aaron-ramsey/profil/spieler/50057 | Q17: debe tenenr un solo urkl | R17: players corrected fbref
A18: 177321 | B18: Abdul Razak | C18: https://fbref.com/en/players/5e61927c/Abdul-Razak | D18: Success | E18: Not found | F18: 33919 | G18: Not found | H18: 180cm | I18: CÃ´te d'Ivoire | J18: MF | K18: Not found | L18: 2010-2011 | M18: 17 years | N18: Manchester City | O18: 2010 | P18: https://www.transfermarkt.com/abdul-razak/profil/spieler/177321 | Q18: debe tenenr un solo urkl | R18: players corrected fbref
A19: 37713 | B19: Cristian Riveros | C19: https://fbref.com/en/players/49ad3514/Cristian-Riveros | D19: Success | E19: Not found | F19: 30240 | G19: Not found | H19: 179cm | I19: Paraguay | J19: MF (CM-DM) | K19: Not found | L19: 2007-2008 | M19: 24 years | N19: Cruz Azul | O19: 2007 | P19: https://www.transfermarkt.com/cristian-riveros/profil/spieler/37713 | Q19: debe tenenr un solo urkl | R19: players corrected fbref
A20: 128909 | B20: Jack Robinson | C20: https://fbref.com/en/players/7399c7a8/Jack-Robinson | D20: Success | E20: Not found | F20: September 1, 1993 (Age:Â 32-096d) | G20: Warrington, England, United Kingdom | H20: 180cm | I20: England eng | J20: DF (CB-FB, left) | K20: Left | L20: 2009-2010 | M20: 15 years | N20: Liverpool | O20: 2009 | P20: https://www.transfermarkt.com/jack-robinson/profil/spieler/128909 | Q20: debe tenenr un solo urkl | R20: players corrected fbref
A21: 14063 | B21: Paul Robinson | C21: https://fbref.com/en/players/80cdbbe1/Paul-Robinson | D21: Success | E21: Not found | F21: 28838 | G21: Not found | H21: 178cm | I21: England eng | J21: DF (CB-FB, left) | K21: Left | L21: 1999-2000 | M21: 20 years | N21: Watford | O21: 1999 | P21: https://www.transfermarkt.com/paul-robinson/profil/spieler/14063 | Q21: debe tenenr un solo urkl | R21: players corrected fbref
A22: 3630 | B22: Paul Robinson | C22: https://fbref.com/en/players/3515ba56/Paul-Robinson | D22: Success | E22: Not found | F22: 29143 | G22: Not found | H22: 193cm | I22: England eng | J22: GK | K22: Right | L22: 1998-1999 | M22: 18 years | N22: Leeds United | O22: 1998 | P22: https://www.transfermarkt.com/paul-robinson/profil/spieler/3630 | Q22: debe tenenr un solo urkl | R22: players corrected fbref
A23: 50174 | B23: Danny Rose | C23: https://fbref.com/en/players/89d10e53/Danny-Rose | D23: Success | E23: Not found | F23: 33056 | G23: Not found | H23: 173cm | I23: England eng | J23: DF-MF (FB, left) | K23: Left | L23: 2008-2009 | M23: 18 years | N23: Watford | O23: 2008 | P23: https://www.transfermarkt.com/danny-rose/profil/spieler/50174 | Q23: debe tenenr un solo urkl | R23: players corrected fbref
A24: 92109 | B24: Ryan Shotton | C24: https://fbref.com/en/players/09f82c6e/Ryan-Shotton | D24: Success | E24: Not found | F24: 32446 | G24: Not found | H24: 191cm | I24: Not found | J24: DF-FW-MF (CB-FB-WM, right) | K24: Right | L24: 2007-2008 | M24: 18 years | N24: Altrincham | O24: 2007 | P24: https://www.transfermarkt.com/ryan-shotton/profil/spieler/92109 | Q24: debe tenenr un solo urkl | R24: players corrected fbref
A25: 35518 | B25: David Silva | C25: https://fbref.com/en/players/e2716bd0/David-Silva | D25: Success | E25: Not found | F25: 31420 | G25: Not found | H25: 170cm | I25: Spain | J25: FW-MF (AM-CM-WM) | K25: Left | L25: 2004-2005 | M25: 18 years | N25: Eibar | O25: 2004 | P25: https://www.transfermarkt.com/david-silva/profil/spieler/35518 | Q25: debe tenenr un solo urkl | R25: players corrected fbref
A26: 44352 | B26: Luis SuÃ¡rez | C26: https://fbref.com/en/players/a6154613/Luis-Suarez | D26: Success | E26: Not found | F26: January 24, 1987 (Age:Â 38-316d) | G26: Salto, Uruguay | H26: 182cm | I26: Uruguay | J26: FW | K26: Right | L26: 2006-2007 | M26: 19 years | N26: Groningen | O26: 2006 | P26: https://www.transfermarkt.com/luis-surez/profil/spieler/44352 | Q26: debe tenenr un solo urkl | R26: players corrected fbref
A27: 44352 | B27: Luis SuÃ¡rez | C27: https://fbref.com/en/players/a6154613/Luis-Suarez | D27: Success | E27: Not found | F27: January 24, 1987 (Age:Â 38-316d) | G27: Salto, Uruguay | H27: 182cm | I27: Uruguay | J27: FW | K27: Right | L27: 2006-2007 | M27: 19 years | N27: Groningen | O27: 2006 | P27: https://www.transfermarkt.com/luis-alberto/profil/spieler/44352 | Q27: debe tenenr un solo urkl | R27: players corrected fbref
A28: 7767 | B28: Fernando Torres | C28: https://fbref.com/en/players/bdf7b97d/Fernando-Torres | D28: Success | E28: Not found | F28: 30761 | G28: Not found | H28: 185cm | I28: Spain | J28: FW | K28: Right | L28: 2001-2002 | M28: 17 years | N28: AtlÃ©tico Madrid | O28: 2001 | P28: https://www.transfermarkt.com/fernando-torres/profil/spieler/7767 | Q28: debe tenenr un solo urkl | R28: players corrected fbref
A29: 7767 | B29: Fernando Torres | C29: https://fbref.com/en/players/bdf7b97d/Fernando-Torres | D29: Success | E29: Not found | F29: 30761 | G29: Not found | H29: 185cm | I29: Spain | J29: FW | K29: Right | L29: 2001-2002 | M29: 17 years | N29: AtlÃ©tico Madrid | O29: 2001 | P29: https://www.transfermarkt.com/fernando/profil/spieler/7767 | Q29: debe tenenr un solo urkl | R29: players corrected fbref
A30: 33544 | B30: Antonio Valencia | C30: https://fbref.com/en/players/08aa17d0/Antonio-Valencia | D30: Success | E30: Not found | F30: 31263 | G30: Not found | H30: 180cm | I30: Ecuador | J30: DF-MF (FB-WM, right) | K30: Right | L30: 2005-2006 | M30: 19 years | N30: Recreativo | O30: 2005 | P30: https://www.transfermarkt.com/antonio-valencia/profil/spieler/33544 | Q30: debe tenenr un solo urkl | R30: players corrected fbref
A31: 35773 | B31: Carlos Vela | C31: https://fbref.com/en/players/e0cd04e0/Carlos-Vela | D31: Success | E31: Not found | F31: 32568 | G31: Not found | H31: 177cm | I31: Mexico | J31: FW-MF | K31: Left | L31: 2006-2007 | M31: 17 years | N31: Salamanca | O31: 2006 | P31: https://www.transfermarkt.com/carlos-vela/profil/spieler/35773 | Q31: debe tenenr un solo urkl | R31: players corrected fbref
A32: 3183 | B32: Patrick Vieira | C32: https://fbref.com/en/players/f90f1086/Patrick-Vieira | D32: Success | E32: Not found | F32: 27934 | G32: Not found | H32: 193cm | I32: France fr Â Other:Â Senegal | J32: MF (CM-DM) | K32: Right | L32: 1995-1996 | M32: 19 years | N32: Cannes | O32: 1995 | P32: https://www.transfermarkt.com/patrick-vieira/profil/spieler/3183 | Q32: debe tenenr un solo urkl | R32: players corrected fbref
A33: 95424 | B33: Kyle Walker | C33: https://fbref.com/en/players/86dd77d1/Kyle-Walker | D33: Success | E33: Not found | F33: May 28, 1990 (Age:Â 35-192d) | G33: Sheffield, England, United Kingdom | H33: 178cm | I33: England eng | J33: DF-MF (FB, right) | K33: Right | L33: 2008-2009 | M33: 18 years | N33: Northampton | O33: 2008 | P33: https://www.transfermarkt.com/kyle-walker/profil/spieler/95424 | Q33: debe tenenr un solo urkl | R33: players corrected fbref
A34: 13683 | B34: Dean Whitehead | C34: https://fbref.com/en/players/a32204c9/Dean-Whitehead | D34: Success | E34: Not found | F34: 29972 | G34: Not found | H34: 180cm | I34: Not found | J34: DF-MF (CM-FB, right) | K34: Right | L34: 2002-2003 | M34: 20 years | N34: Oxford United | O34: 2002 | P34: https://www.transfermarkt.com/dean-whitehead/profil/spieler/13683 | Q34: debe tenenr un solo urkl | R34: players corrected fbref
A35: 119269 | B35: Shane Duffy | C35: https://fbref.com/en/players/7314bba4/Shane-Duffyhttps://fbref.com/en/players/fa6292e2/Bryan-Ruiz | D35: Success | E35: Not found | F35: January 1, 1992 (Age:Â 33-339d) | G35: Derry, Northern Ireland, United Kingdom | H35: 193cm | I35: Republic of Ireland ie Â Other:Â Northern Ireland | J35: DF-MF (CB, right) | K35: Right | L35: 2010-2011 | M35: 18 years | N35: Burnley | O35: 2010 | P35: https://www.transfermarkt.com/shane-duffy/profil/spieler/119269 | Q35: debe tenenr un solo urkl | R35: players corrected fbref
A36: 119269 | B36: Shane Duffy | C36: https://fbref.com/en/players/7314bba4/Shane-Duffy | D36: Success | E36: Not found | F36: January 1, 1992 (Age:Â 33-339d) | G36: Derry, Northern Ireland, United Kingdom | H36: 193cm | I36: Republic of Ireland ie Â Other:Â Northern Ireland | J36: DF-MF (CB, right) | K36: Right | L36: 2010-2011 | M36: 18 years | N36: Burnley | O36: 2010 | P36: https://www.transfermarkt.com/shane-duffy/profil/spieler/119269 | Q36: debe tenenr un solo urkl | R36: players corrected fbref
A37: 119269 | B37: Shane Duffy | C37: https://fbref.com/en/players/7314bba4/Shane-Duffy | D37: Success | E37: Not found | F37: January 1, 1992 (Age:Â 33-339d) | G37: Derry, Northern Ireland, United Kingdom | H37: 193cm | I37: Republic of Ireland ie Â Other:Â Northern Ireland | J37: DF-MF (CB, right) | K37: Right | L37: 2010-2011 | M37: 18 years | N37: Burnley | O37: 2010 | P37: https://www.transfermarkt.com/michael-duff/profil/spieler/119269 | Q37: debe tenenr un solo urkl | R37: players corrected fbref
A38: 93056 | B38: Emmanuel Frimpong | C38: https://fbref.com/en/players/524617b5/Emmanuel-Frimpong | D38: Success | E38: Not found | F38: 33613 | G38: Not found | H38: 178cm | I38: Ghana gh Â Other:Â England | J38: MF (DM) | K38: Right | L38: 2011-2012 | M38: 19 years | N38: Arsenal | O38: 2011 | P38: https://www.transfermarkt.com/emmanuel-frimpong/profil/spieler/93056 | Q38: debe tenenr un solo urkl | R38: players corrected fbref
A39: 66550 | B39: Ã€ngel Rangel | C39: https://fbref.com/en/players/93ee387c/Angel-Rangel | D39: Success | E39: Not found | F39: 30252 | G39: Not found | H39: 188cm | I39: Not found | J39: DF (FB, right) | K39: Right | L39: 2007-2008 | M39: 24 years | N39: Swansea City | O39: 2007 | P39: https://www.transfermarkt.com/ngel-rangel/profil/spieler/66550 | Q39: debe tenenr un solo urkl | R39: players corrected fbref
A40: 125117 | B40: Joe Riley | C40: https://fbref.com/en/players/63dd1061/Joe-Riley | D40: Success | E40: Not found | F40: 33524 | G40: Not found | H40: 183cm | I40: Not found | J40: DF (FB, right) | K40: Right | L40: 2011-2012 | M40: 19 years | N40: Bolton | O40: 2011 | P40: https://www.transfermarkt.com/joe-riley/profil/spieler/125117 | Q40: debe tenenr un solo urkl | R40: players corrected fbref
...
